<?xml version="1.0" encoding="utf-8"?>
<!-- This URDF was automatically created by SolidWorks to URDF Exporter! Originally created by Stephen Brawner (brawner@gmail.com) 
     Commit Version: 1.6.0-4-g7f85cfe  Build Version: 1.6.7995.38578
     For more information, please see http://wiki.ros.org/sw_urdf_exporter -->
<robot
  name="AgribotURDF7_withsensors">
  <link
    name="base_link">
    <inertial>
      <origin
        xyz="-0.0430250954057444 -0.0246392144099035 -0.216670102531587"
        rpy="0 0 0" />
      <mass
        value="42.7274264703138" />
      <inertia
        ixx="1.21966121753246"
        ixy="0.00406966070672543"
        ixz="0.000339980127575844"
        iyy="3.17622187148375"
        iyz="0.000152831870700138"
        izz="4.18415118315828" />
    </inertial>
    <visual>
      <origin
        xyz="0 0 0"
        rpy="0 0 0" />
      <geometry>
        <mesh
          filename="package://agribotv2/meshes/base_link.STL" />
      </geometry>
      <material
        name="">
        <color
          rgba="0.866666666666667 0.909803921568627 1 1" />
      </material>
    </visual>
    <collision>
      <origin
        xyz="0 0 0"
        rpy="0 0 0" />
      <geometry>
        <mesh
          filename="package://agribotv2/meshes/base_link.STL" />
      </geometry>
    </collision>
  </link>
  <link
    name="Wheel1">
    <inertial>
      <origin
        xyz="0.000307536481249371 -0.00350451467198853 0.000663792589480974"
        rpy="0 0 0" />
      <mass
        value="1.03557344582628" />
      <inertia
        ixx="0.00276614414011517"
        ixy="-3.01029470231312E-07"
        ixz="3.01406031283371E-07"
        iyy="0.00490633134158487"
        iyz="-6.5532319628811E-07"
        izz="0.00276665519043664" />
    </inertial>
    <visual>
      <origin
        xyz="0 0 0"
        rpy="0 0 0" />
      <geometry>
        <mesh
          filename="package://agribotv2/meshes/Wheel1.STL" />
      </geometry>
      <material
        name="">
        <color
          rgba="0 0 0 1" />
      </material>
    </visual>
    <collision>
      <origin
        xyz="0 0 0"
        rpy="0 0 0" />
      <geometry>
        <mesh
          filename="package://agribotv2/meshes/Wheel1.STL" />
      </geometry>
    </collision>
    <gazebo reference="Wheel1">
      <mu1>0.0</mu1>
      <mu2>0.0</mu2>
      <kp>10000000.0</kp>
      <kd>1.0</kd>
      <material>Gazebo/Black</material>
    </gazebo>
  </link>
  <joint
    name="Wheel1J"
    type="continuous">
    <origin
      xyz="0.433437506660347 -0.450475552237037 -0.566999999998756"
      rpy="0 0 0" />
    <parent
      link="base_link" />
    <child
      link="Wheel1" />
    <axis
      xyz="0 1 0" />
    <limit
      effort="200"
      velocity="1000" />
    <dynamics
      damping="0.35"
      friction="8" />
  </joint>
  <link
    name="Wheel2">
    <inertial>
      <origin
        xyz="0.000505499867033757 0.0013799562469069 0.000528837568406437"
        rpy="0 0 0" />
      <mass
        value="1.03557344582626" />
      <inertia
        ixx="0.00276638179288642"
        ixy="-4.9660554934376E-07"
        ixz="3.94739510536276E-07"
        iyy="0.00490633134158467"
        iyz="-5.22924630345775E-07"
        izz="0.00276641753766517" />
    </inertial>
    <visual>
      <origin
        xyz="0 0 0"
        rpy="0 0 0" />
      <geometry>
        <mesh
          filename="package://agribotv2/meshes/Wheel2.STL" />
      </geometry>
      <material
        name="">
        <color
          rgba="0 0 0 1" />
      </material>
    </visual>
    <collision>
      <origin
        xyz="0 0 0"
        rpy="0 0 0" />
      <geometry>
        <mesh
          filename="package://agribotv2/meshes/Wheel2.STL" />
      </geometry>
    </collision>
    <gazebo reference="Wheel2">
      <mu1>0.0</mu1>
      <mu2>0.0</mu2>
      <kp>10000000.0</kp>
      <kd>1.0</kd>
      <material>Gazebo/Black</material>
    </gazebo>
  </link>
  <joint
    name="Wheel2J"
    type="continuous">
    <origin
      xyz="-0.476562493339175 -0.455360023155968 -0.566999999998177"
      rpy="0 0 0" />
    <parent
      link="base_link" />
    <child
      link="Wheel2" />
    <axis
      xyz="0 1 0" />
    <limit
      effort="200"
      velocity="1000" />
    <dynamics
      damping="0.35"
      friction="8" />
  </joint>
  <link
    name="Wheel3">
    <inertial>
      <origin
        xyz="0.000307536481250315 -0.0013799562469465 -0.000663792589615943"
        rpy="0 0 0" />
      <mass
        value="1.03557344582624" />
      <inertia
        ixx="0.002766144140115"
        ixy="3.01029470242429E-07"
        ixz="-3.01406031338346E-07"
        iyy="0.0049063313415846"
        iyz="-6.55323201718687E-07"
        izz="0.00276665519043652" />
    </inertial>
    <visual>
      <origin
        xyz="0 0 0"
        rpy="0 0 0" />
      <geometry>
        <mesh
          filename="package://agribotv2/meshes/Wheel3.STL" />
      </geometry>
      <material
        name="">
        <color
          rgba="0 0 0 1" />
      </material>
    </visual>
    <collision>
      <origin
        xyz="0 0 0"
        rpy="0 0 0" />
      <geometry>
        <mesh
          filename="package://agribotv2/meshes/Wheel3.STL" />
      </geometry>
    </collision>
    <gazebo reference="Wheel3">
      <mu1>0.0</mu1>
      <mu2>0.0</mu2>
      <kp>10000000.0</kp>
      <kd>1.0</kd>
      <material>Gazebo/Black</material>
    </gazebo>
  </link>
  <joint
    name="Wheel3J"
    type="continuous">
    <origin
      xyz="-0.476562493339655 0.406386547977788 -0.567000000001082"
      rpy="0 0 0" />
    <parent
      link="base_link" />
    <child
      link="Wheel3" />
    <axis
      xyz="0 1 0" />
    <limit
      effort="200"
      velocity="1000" />
    <dynamics
      damping="0.35"
      friction="8" />
  </joint>
  <link
    name="Wheel4">
    <inertial>
      <origin
        xyz="-0.000307536481244819 -0.00626442716576215 0.000663792589892132"
        rpy="0 0 0" />
      <mass
        value="1.03557344582622" />
      <inertia
        ixx="0.00276614414011497"
        ixy="-3.0102947023333E-07"
        ixz="-3.0140603139485E-07"
        iyy="0.00490633134158452"
        iyz="6.5532320171179E-07"
        izz="0.00276665519043647" />
    </inertial>
    <visual>
      <origin
        xyz="0 0 0"
        rpy="0 0 0" />
      <geometry>
        <mesh
          filename="package://agribotv2/meshes/Wheel4.STL" />
      </geometry>
      <material
        name="">
        <color
          rgba="0 0 0 1" />
      </material>
    </visual>
    <collision>
      <origin
        xyz="0 0 0"
        rpy="0 0 0" />
      <geometry>
        <mesh
          filename="package://agribotv2/meshes/Wheel4.STL" />
      </geometry>
    </collision>
    <gazebo reference="Wheel4">
      <mu1>0.0</mu1>
      <mu2>0.0</mu2>
      <kp>10000000.0</kp>
      <kd>1.0</kd>
      <material>Gazebo/Black</material>
    </gazebo>
  </link>
  <joint
    name="Wheel4J"
    type="continuous">
    <origin
      xyz="0.433437506665098 0.411271018896604 -0.566999999999163"
      rpy="0 0 0" />
    <parent
      link="base_link" />
    <child
      link="Wheel4" />
    <axis
      xyz="0 1 0" />
    <limit
      effort="200"
      velocity="1000" />
    <dynamics
      damping="0.35"
      friction="8" />
  </joint>
  <link
    name="Seeder">
    <inertial>
      <origin
        xyz="-0.00565167876018524 8.97751948416015E-05 -0.0302124488119062"
        rpy="0 0 0" />
      <mass
        value="1.19140713287901" />
      <inertia
        ixx="0.00572757836043353"
        ixy="-1.1313835092507E-07"
        ixz="8.44849373187445E-06"
        iyy="0.00576192418600774"
        iyz="-1.14186514103829E-07"
        izz="0.000396595843384034" />
    </inertial>
    <visual>
      <origin
        xyz="0 0 0"
        rpy="0 0 0" />
      <geometry>
        <mesh
          filename="package://agribotv2/meshes/Seeder.STL" />
      </geometry>
      <material
        name="">
        <color
          rgba="0 0 1 1" />
      </material>
    </visual>
    <collision>
      <origin
        xyz="0 0 0"
        rpy="0 0 0" />
      <geometry>
        <mesh
          filename="package://agribotv2/meshes/Seeder.STL" />
      </geometry>
    </collision>
    <gazebo reference="Seeder">
      <material>Gazebo/Blue</material>
    </gazebo>
  </link>
  <joint
    name="SeederJ"
    type="fixed">
    <origin
      xyz="0.121937506662726 -0.0244867375890883 -0.293552999840268"
      rpy="0 0 -3.14159265358979" />
    <parent
      link="base_link" />
    <child
      link="Seeder" />
    <axis
      xyz="0 0 -1" />
  </joint>
  <link
    name="US1">
    <inertial>
      <origin
        xyz="0.00206896551724634 3.33066907387547E-16 3.33066907387547E-16"
        rpy="0 0 0" />
      <mass
        value="0.0221388034298472" />
      <inertia
        ixx="2.64176997479263E-06"
        ixy="-1.02844849101362E-21"
        ixz="-2.64697796016969E-21"
        iyy="3.07489815818501E-06"
        iyz="-3.49786551674547E-24"
        izz="3.07489815818501E-06" />
    </inertial>
    <visual>
      <origin
        xyz="0 0 0"
        rpy="0 0 0" />
      <geometry>
        <mesh
          filename="package://agribotv2/meshes/US1.STL" />
      </geometry>
      <material
        name="">
        <color
          rgba="0.298039215686275 0.298039215686275 0.298039215686275 1" />
      </material>
    </visual>
    <collision>
      <origin
        xyz="0 0 0"
        rpy="0 0 0" />
      <geometry>
        <mesh
          filename="package://agribotv2/meshes/US1.STL" />
      </geometry>
    </collision>
  </link>
  <joint
    name="us1J"
    type="fixed">
    <origin
      xyz="0.138074753587277 -0.422471907443304 -0.311999999999983"
      rpy="1.5707963267949 0 -0.62831853071796" />
    <parent
      link="base_link" />
    <child
      link="US1" />
    <axis
      xyz="0 0 0" />
  </joint>
  <link
    name="US2">
    <inertial>
      <origin
        xyz="0.00192710924089134 0 0.000752906558083577"
        rpy="0 0 0" />
      <mass
        value="0.0221388034298472" />
      <inertia
        ixx="2.69912772377299E-06"
        ixy="8.7799853058982E-22"
        ixz="-1.46810579493591E-07"
        iyy="3.07489815818501E-06"
        iyz="3.54420660372501E-22"
        izz="3.01754040920466E-06" />
    </inertial>
    <visual>
      <origin
        xyz="0 0 0"
        rpy="0 0 0" />
      <geometry>
        <mesh
          filename="package://agribotv2/meshes/US2.STL" />
      </geometry>
      <material
        name="">
        <color
          rgba="0.298039215686275 0.298039215686275 0.298039215686275 1" />
      </material>
    </visual>
    <collision>
      <origin
        xyz="0 0 0"
        rpy="0 0 0" />
      <geometry>
        <mesh
          filename="package://agribotv2/meshes/US2.STL" />
      </geometry>
    </collision>
  </link>
  <joint
    name="us2J"
    type="fixed">
    <origin
      xyz="0.45 -0.281804434077445 -0.311999999999983"
      rpy="-1.5707963267949 0 0" />
    <parent
      link="base_link" />
    <child
      link="US2" />
    <axis
      xyz="0 0 0" />
  </joint>
  <link
    name="US3">
    <inertial>
      <origin
        xyz="0.00206896551724167 -2.77555756156289E-16 9.15933995315754E-16"
        rpy="0 0 0" />
      <mass
        value="0.0221388034298473" />
      <inertia
        ixx="2.64176997479264E-06"
        ixy="-9.25525158141707E-22"
        ixz="1.05879118406788E-22"
        iyy="3.07489815818503E-06"
        iyz="-7.69033112143488E-24"
        izz="3.07489815818503E-06" />
    </inertial>
    <visual>
      <origin
        xyz="0 0 0"
        rpy="0 0 0" />
      <geometry>
        <mesh
          filename="package://agribotv2/meshes/US3.STL" />
      </geometry>
      <material
        name="">
        <color
          rgba="0.298039215686275 0.298039215686275 0.298039215686275 1" />
      </material>
    </visual>
    <collision>
      <origin
        xyz="0 0 0"
        rpy="0 0 0" />
      <geometry>
        <mesh
          filename="package://agribotv2/meshes/US3.STL" />
      </geometry>
    </collision>
  </link>
  <joint
    name="us3J"
    type="fixed">
    <origin
      xyz="0.45 0.232830958899269 -0.311999999999983"
      rpy="1.5707963267949 0 -0.372456753034098" />
    <parent
      link="base_link" />
    <child
      link="US3" />
    <axis
      xyz="0 0 0" />
  </joint>
  <link
    name="US4">
    <inertial>
      <origin
        xyz="0.00206896551724578 4.44089209850063E-16 -9.99200722162641E-16"
        rpy="0 0 0" />
      <mass
        value="0.0221388034298472" />
      <inertia
        ixx="2.64176997479263E-06"
        ixy="-1.02844849101369E-21"
        ixz="1.90582413132218E-21"
        iyy="3.07489815818501E-06"
        iyz="3.49786551674408E-24"
        izz="3.07489815818501E-06" />
    </inertial>
    <visual>
      <origin
        xyz="0 0 0"
        rpy="0 0 0" />
      <geometry>
        <mesh
          filename="package://agribotv2/meshes/US4.STL" />
      </geometry>
      <material
        name="">
        <color
          rgba="0.298039215686275 0.298039215686275 0.298039215686275 1" />
      </material>
    </visual>
    <collision>
      <origin
        xyz="0 0 0"
        rpy="0 0 0" />
      <geometry>
        <mesh
          filename="package://agribotv2/meshes/US4.STL" />
      </geometry>
    </collision>
  </link>
  <joint
    name="us4J"
    type="fixed">
    <origin
      xyz="0.13807475358728 0.373498432265127 -0.311999999999983"
      rpy="1.5707963267949 0 0.62831853071796" />
    <parent
      link="base_link" />
    <child
      link="US4" />
    <axis
      xyz="0 0 0" />
  </joint>

  <link name="camera">
    <inertial>
      <origin xyz="-0.0125 0 -0.0107" rpy="0 0 0" />
      <mass value="0.06" />
      <!-- FIXED: Off-diagonals (xy, xz, yz) MUST be 0 -->
      <inertia
        ixx="0.0001"
        ixy="0.0"
        ixz="0.0"
        iyy="0.0001"
        iyz="0.0"
        izz="0.0001" />
    </inertial>
    
    <visual>
      <origin xyz="0 0 0" rpy="0 0 0" />
      <geometry>
        <mesh filename="package://agribotv2/meshes/Camera.STL" />
      </geometry>
      <material name="">
        <color rgba="0.79 0.82 0.93 1" />
      </material>
    </visual>
    
    <!-- FIXED: Syntax error removed, using simple Box for physics stability -->
    <collision>
      <origin xyz="0 0 0" rpy="0 0 0" />
      <geometry>
        <!-- A simple box is much better for simulation stability than a mesh -->
        <box size="0.05 0.05 0.05"/>
      </geometry>
    </collision>
  </link>
  <joint
    name="camJ"
    type="fixed">
    <origin
      xyz="0.40143750666272 -0.0333712085079144 -0.33676308034937"
      rpy="0 0 0" />
    <parent
      link="base_link" />
    <child
      link="camera" />
  </joint>
  <gazebo>

  <!-- IMU SENSOR -->
  <gazebo reference="imu_link">
    <sensor name="imu_sensor" type="imu">
      <always_on>1</always_on>
      <update_rate>50</update_rate>
      <visualize>true</visualize>
      <topic>/imu</topic>
      <frame_id>imu_link</frame_id>
      <gz_frame_id>imu_link</gz_frame_id>
    </sensor>
  </gazebo>

  <!-- GPS SENSOR -->
  <gazebo reference="gps_link">
    <sensor name="gps_sensor" type="navsat">
      <always_on>1</always_on>
      <update_rate>1</update_rate>
      <topic>/gps/fix</topic>
      <frame_id>gps_link</frame_id>
      <gz_frame_id>gps_link</gz_frame_id>
    </sensor>
  </gazebo>

    <!-- <plugin filename="libignition-gazebo-diff-drive-system.so" name="ignition::gazebo::systems::DiffDrive">
      <left_joint>Wheel4J</left_joint>
      <right_joint>Wheel1J</right_joint>
      <wheel_separation>0.866</wheel_separation>
      <wheel_radius>0.1</wheel_radius>
      <odom_publish_frequency>1</odom_publish_frequency>
      <topic>/cmd_vel</topic>
      <odom_topic>/odometry</odom_topic>
      <tf_topic>/tf</tf_topic>
      <frame_id>odom</frame_id>
      <child_frame_id>base_link</child_frame_id>
      <max_linear_acceleration>20.0</max_linear_acceleration>
      <min_linear_acceleration>-20.0</min_linear_acceleration>
      <max_angular_acceleration>20.0</max_angular_acceleration>
      <min_angular_acceleration>-20.0</min_angular_acceleration>
      <max_linear_velocity>4.0</max_linear_velocity>
      <min_linear_velocity>-4.0</min_linear_velocity>
      <max_angular_velocity>4.0</max_angular_velocity>
      <min_angular_velocity>-4.0</min_angular_velocity>
    </plugin>

    <plugin filename="libignition-gazebo-diff-drive-system.so" name="ignition::gazebo::systems::DiffDrive">
      <left_joint>Wheel3J</left_joint>
      <right_joint>Wheel2J</right_joint>
      <wheel_separation>0.866</wheel_separation>
      <wheel_radius>0.1</wheel_radius>
      <odom_publish_frequency>1</odom_publish_frequency>
      <topic>/cmd_vel</topic>
      <max_linear_acceleration>20.0</max_linear_acceleration>
      <min_linear_acceleration>-20.0</min_linear_acceleration>
      <max_angular_acceleration>20.0</max_angular_acceleration>
      <min_angular_acceleration>-20.0</min_angular_acceleration>
      <max_linear_velocity>4.0</max_linear_velocity>
      <min_linear_velocity>-4.0</min_linear_velocity>
      <max_angular_velocity>4.0</max_angular_velocity>
      <min_angular_velocity>-4.0</min_angular_velocity>
    </plugin>
    <plugin filename="libignition-gazebo-joint-state-publisher-system.so" name="ignition::gazebo::systems::JointStatePublisher">
      <topic>joint_states</topic>
      <joint_name>Wheel1J</joint_name>
      <joint_name>Wheel2J</joint_name>
      <joint_name>Wheel3J</joint_name>
      <joint_name>Wheel4J</joint_name>
    </plugin>
  </gazebo> -->
  <!-- FRONT WHEELS (Master: Publishes Odom, No TF) -->

  <!-- modified to take the odom from the ekf instead of diff drive -->
    <plugin filename="libignition-gazebo-diff-drive-system.so" name="ignition::gazebo::systems::DiffDrive">
      <left_joint>Wheel4J</left_joint>
      <right_joint>Wheel1J</right_joint>
      <wheel_separation>0.866</wheel_separation>
      <wheel_radius>0.1</wheel_radius>
      
      <!-- FIXED: Changed from 1 to 30 for smoother EKF -->
      <odom_publish_frequency>30</odom_publish_frequency>
      
      <topic>/cmd_vel</topic>
      <odom_topic>/odometry</odom_topic>
      
      <!-- DELETED: <tf_topic>/tf</tf_topic> so it stops fighting RViz -->
      
      <frame_id>odom</frame_id>
      <child_frame_id>base_link</child_frame_id>
      
      <max_linear_acceleration>20.0</max_linear_acceleration>
      <min_linear_acceleration>-20.0</min_linear_acceleration>
      <max_angular_acceleration>20.0</max_angular_acceleration>
      <min_angular_acceleration>-20.0</min_angular_acceleration>
      <max_linear_velocity>4.0</max_linear_velocity>
      <min_linear_velocity>-4.0</min_linear_velocity>
      <max_angular_velocity>4.0</max_angular_velocity>
      <min_angular_velocity>-4.0</min_angular_velocity>
    </plugin>

    <!-- REAR WHEELS (Slave: Drives motors, Ignores Odom) -->
    <plugin filename="libignition-gazebo-diff-drive-system.so" name="ignition::gazebo::systems::DiffDrive">
      <left_joint>Wheel3J</left_joint>
      <right_joint>Wheel2J</right_joint>
      <wheel_separation>0.866</wheel_separation>
      <wheel_radius>0.1</wheel_radius>
      
      <odom_publish_frequency>30</odom_publish_frequency>
      
      <topic>/cmd_vel</topic>
      
      <!-- SAFETY: Send this to a dummy topic so it doesn't double-count odom -->
      <odom_topic>/odometry_rear_ignore</odom_topic>
      
      <max_linear_acceleration>20.0</max_linear_acceleration>
      <min_linear_acceleration>-20.0</min_linear_acceleration>
      <max_angular_acceleration>20.0</max_angular_acceleration>
      <min_angular_acceleration>-20.0</min_angular_acceleration>
      <max_linear_velocity>4.0</max_linear_velocity>
      <min_linear_velocity>-4.0</min_linear_velocity>
      <max_angular_velocity>4.0</max_angular_velocity>
      <min_angular_velocity>-4.0</min_angular_velocity>
    </plugin>

    <plugin filename="libignition-gazebo-joint-state-publisher-system.so" name="ignition::gazebo::systems::JointStatePublisher">
      <topic>joint_states</topic>
      <joint_name>Wheel1J</joint_name>
      <joint_name>Wheel2J</joint_name>
      <joint_name>Wheel3J</joint_name>
      <joint_name>Wheel4J</joint_name>
      <joint_name>camJ</joint_name> 
      <joint_name>imu_joint</joint_name>
      <joint_name>gps_joint</joint_name>
    </plugin>
  </gazebo>
<!--   
  <gazebo reference="US1">
    <sensor name="US1_sensor" type="gpu_lidar">
      <pose>0 0 0 -1.5708 0 0</pose>
      <visualize>true</visualize>
      <update_rate>20</update_rate>
      <frame_id>US1</frame_id>
      <ray>
        <scan>
          <horizontal>
            <samples>60</samples>
            <resolution>1</resolution>
            <min_angle>-0.5236</min_angle>
            <max_angle>0.5236</max_angle>
          </horizontal>
        </scan>
        <range>
          <min>0.25</min>
          <max>4.0</max>
          <resolution>0.01</resolution>
        </range>
      </ray>
      <topic>/ultra/us1</topic>
    </sensor>
  </gazebo>

  <gazebo reference="US2">
    <sensor name="US2_sensor" type="gpu_lidar">
      <pose>0 0 0 1.5708 0 0</pose>
      <visualize>true</visualize>
      <update_rate>20</update_rate>
      <frame_id>US2</frame_id>
      <ray>
        <scan>
          <horizontal>
            <samples>60</samples>
            <resolution>1</resolution>
            <min_angle>-0.5236</min_angle>
            <max_angle>0.5236</max_angle>
          </horizontal>
        </scan>
        <range>
          <min>0.25</min>
          <max>4.0</max>
          <resolution>0.01</resolution>
        </range>
      </ray>
      <topic>/ultra/us2</topic>
    </sensor>
  </gazebo>

  <gazebo reference="US3">
    <sensor name="US3_sensor" type="gpu_lidar">
      <pose>0 0 0 -1.5708 0 0</pose>
      <visualize>true</visualize>
      <update_rate>20</update_rate>
      <frame_id>US3</frame_id>
      <ray>
        <scan>
          <horizontal>
            <samples>60</samples>
            <resolution>1</resolution>
            <min_angle>-0.5236</min_angle>
            <max_angle>0.5236</max_angle>
          </horizontal>
        </scan>
        <range>
          <min>0.25</min>
          <max>4.0</max>
          <resolution>0.01</resolution>
        </range>
      </ray>
      <topic>/ultra/us3</topic>
    </sensor>
  </gazebo>

  <gazebo reference="US4">
    <sensor name="US4_sensor" type="gpu_lidar">
      <pose>0 0 0 -1.5708 0 0</pose>
      <visualize>true</visualize>
      <update_rate>20</update_rate>
      <frame_id>US4</frame_id>
      <ray>
        <scan>
          <horizontal>
            <samples>60</samples>
            <resolution>1</resolution>
            <min_angle>-0.5236</min_angle>
            <max_angle>0.5236</max_angle>
          </horizontal>
        </scan>
        <range>
          <min>0.25</min>
          <max>4.0</max>
          <resolution>0.01</resolution>
        </range>
      </ray>
      <topic>/ultra/us4</topic>
    </sensor>
  </gazebo>

  <gazebo reference="camera">
    <sensor name="camera_sensor" type="camera">
      <pose>0 0 0 0 0 0</pose>
      <visualize>true</visualize>
      <update_rate>30</update_rate>
      <frame_id>camera</frame_id>
      <camera>
        <horizontal_fov>1.047</horizontal_fov>
        <image>
          <width>640</width>
          <height>480</height>
        </image>
        <clip>
          <near>0.1</near>
          <far>100</far>
        </clip>
      </camera>
      <topic>/camera/image_raw</topic>
    </sensor>
  </gazebo> -->
<!-- ULTRASONIC 1 -->
  <gazebo reference="US1">
    <sensor name="US1_sensor" type="gpu_lidar">
      <pose>0 0 0 -1.5708 0 0</pose>
      <visualize>true</visualize>
      <update_rate>20</update_rate>
      
      <!-- Force the Frame ID to match ROS -->
      <frame_id>US1</frame_id>
      <gz_frame_id>US1</gz_frame_id> 
      
      <ray>
        <scan>
          <horizontal>
            <samples>60</samples>
            <resolution>1</resolution>
            <min_angle>-0.5236</min_angle>
            <max_angle>0.5236</max_angle>
          </horizontal>
        </scan>
        <range>
          <min>0.25</min>
          <max>4.0</max>
          <resolution>0.01</resolution>
        </range>
      </ray>
      <topic>/ultra/us1</topic>
    </sensor>
  </gazebo>

  <!-- ULTRASONIC 2 -->
  <gazebo reference="US2">
    <sensor name="US2_sensor" type="gpu_lidar">
      <pose>0 0 0 1.5708 0 0</pose>
      <visualize>true</visualize>
      <update_rate>20</update_rate>
      
      <!-- Force the Frame ID -->
      <frame_id>US2</frame_id>
      <gz_frame_id>US2</gz_frame_id>

      <ray>
        <scan>
          <horizontal>
            <samples>60</samples>
            <resolution>1</resolution>
            <min_angle>-0.5236</min_angle>
            <max_angle>0.5236</max_angle>
          </horizontal>
        </scan>
        <range>
          <min>0.25</min>
          <max>4.0</max>
          <resolution>0.01</resolution>
        </range>
      </ray>
      <topic>/ultra/us2</topic>
    </sensor>
  </gazebo>

  <!-- ULTRASONIC 3 -->
  <gazebo reference="US3">
    <sensor name="US3_sensor" type="gpu_lidar">
      <pose>0 0 0 -1.5708 0 0</pose>
      <visualize>true</visualize>
      <update_rate>20</update_rate>
      
      <!-- Force the Frame ID -->
      <frame_id>US3</frame_id>
      <gz_frame_id>US3</gz_frame_id>

      <ray>
        <scan>
          <horizontal>
            <samples>60</samples>
            <resolution>1</resolution>
            <min_angle>-0.5236</min_angle>
            <max_angle>0.5236</max_angle>
          </horizontal>
        </scan>
        <range>
          <min>0.25</min>
          <max>4.0</max>
          <resolution>0.01</resolution>
        </range>
      </ray>
      <topic>/ultra/us3</topic>
    </sensor>
  </gazebo>

  <!-- ULTRASONIC 4 -->
  <gazebo reference="US4">
    <sensor name="US4_sensor" type="gpu_lidar">
      <pose>0 0 0 -1.5708 0 0</pose>
      <visualize>true</visualize>
      <update_rate>20</update_rate>
      
      <!-- Force the Frame ID -->
      <frame_id>US4</frame_id>
      <gz_frame_id>US4</gz_frame_id>

      <ray>
        <scan>
          <horizontal>
            <samples>60</samples>
            <resolution>1</resolution>
            <min_angle>-0.5236</min_angle>
            <max_angle>0.5236</max_angle>
          </horizontal>
        </scan>
        <range>
          <min>0.25</min>
          <max>4.0</max>
          <resolution>0.01</resolution>
        </range>
      </ray>
      <topic>/ultra/us4</topic>
    </sensor>
  </gazebo>

  <!-- CAMERA -->
  <gazebo reference="camera">
    <sensor name="camera" type="camera">
      <pose>0 0 0 0 0 0</pose>
      <visualize>true</visualize>
      <update_rate>30</update_rate>
      
      <frame_id>camera</frame_id>
      <gz_frame_id>camera</gz_frame_id>

      <camera>
        <horizontal_fov>1.047</horizontal_fov>
        <image>
          <width>640</width>
          <height>480</height>
        </image>
        <clip>
          <near>0.1</near>
          <far>100</far>
        </clip>
      </camera>
      <topic>/camera/image_raw</topic>
    </sensor>
  </gazebo>

  <gazebo reference="base_link">
    <sensor name="imu_sensor" type="imu">
      <always_on>1</always_on>
      <update_rate>100</update_rate>
      <visualize>true</visualize>
      <frame_id>imu_link</frame_id>
      <topic>/imu</topic>
    </sensor>
    <sensor name="gps_sensor" type="navsat">
      <always_on>1</always_on>
      <update_rate>1</update_rate>
      <topic>/gps/fix</topic>
      <frame_id>gps_link</frame_id>

    </sensor>
  </gazebo>
</robot>