<sdf version='1.9'>
  <world name='SinaiAgri'>
    <physics name='1ms' type='ignored'>
      <max_step_size>0.001</max_step_size>
      <real_time_factor>1</real_time_factor>
      <real_time_update_rate>1000</real_time_update_rate>
    </physics>
    <plugin name='gz::sim::systems::Physics' filename='ignition-gazebo-physics-system'/>
    <plugin name='gz::sim::systems::UserCommands' filename='ignition-gazebo-user-commands-system'/>
    <plugin name='gz::sim::systems::SceneBroadcaster' filename='ignition-gazebo-scene-broadcaster-system'/>
    <plugin name='gz::sim::systems::Contact' filename='ignition-gazebo-contact-system'/>
    <plugin name='gz::sim::systems::Sensors' filename='ignition-gazebo-sensors-system'>
      <render_engine>ogre</render_engine>
    </plugin>
    <gravity>0 0 -9.8</gravity>
    <magnetic_field>6e-06 2.3e-05 -4.2e-05</magnetic_field>
    <atmosphere type='adiabatic'/>
    <scene>
      <ambient>0.4 0.4 0.4 1</ambient>
      <background>0.7 0.7 0.7 1</background>
      <shadows>true</shadows>
    </scene>
    <model name='ground_plane'>
      <static>true</static>
      <link name='link'>
        <collision name='collision'>
          <geometry>
            <plane>
              <normal>0 0 1</normal>
              <size>100 100</size>
            </plane>
          </geometry>
          <surface>
            <friction>
              <ode/>
            </friction>
            <bounce/>
            <contact/>
          </surface>
        </collision>
        <visual name='visual'>
          <geometry>
            <plane>
              <normal>0 0 1</normal>
              <size>20 20</size>
            </plane>
          </geometry>
          <material>
            <ambient>0.8 0.7 0.6 1</ambient>
            <diffuse>0.8 0.7 0.6 1</diffuse>
            <specular>0.1 0.1 0.1 1</specular>
            <script>
              <uri>model://sand_ground/scripts</uri>
              <uri>model://sand_ground/textures</uri>
              <name>Sand/Diffuse</name>
            </script>
          </material>
        </visual>
        <pose>0 0 0 0 -0 0</pose>
        <inertial>
          <pose>0 0 0 0 -0 0</pose>
          <mass>1</mass>
          <inertia>
            <ixx>1</ixx>
            <ixy>0</ixy>
            <ixz>0</ixz>
            <iyy>1</iyy>
            <iyz>0</iyz>
            <izz>1</izz>
          </inertia>
        </inertial>
        <enable_wind>false</enable_wind>
      </link>
      <pose>0 0 0 0 -0 0</pose>
      <self_collide>false</self_collide>
    </model>
    
    <!-- Plant boxes matching farm_textured.sdf -->
    <model name='plant_0_0'>
      <static>true</static>
      <link name='link'>
        <pose>2.0 -3.0 0 0 0 0</pose>
        <visual name='visual'>
          <geometry>
            <mesh>
              <uri>model://big_plant/mesh/big_plant.stl</uri>
              <scale>1 1 1</scale>
            </mesh>
          </geometry>
        </visual>
        <collision name='collision'>
          <geometry>
            <box>
              <size>0.3 0.3 0.6</size>
            </box>
          </geometry>
        </collision>
      </link>
    </model>

    <model name='plant_1_0'>
      <static>true</static>
      <link name='link'>
        <pose>2.0 -1.0 0 0 0 0</pose>
        <visual name='visual'>
          <geometry>
            <mesh>
              <uri>model://big_plant/mesh/big_plant.stl</uri>
              <scale>1 1 1</scale>
            </mesh>
          </geometry>
        </visual>
        <collision name='collision'>
          <geometry>
            <box>
              <size>0.5 0.5 1.0</size>
            </box>
          </geometry>
        </collision>
      </link>
    </model>

    <model name='plant_1_1'>
      <static>true</static>
      <link name='link'>
        <pose>3.0 -1.0 0 0 0 0</pose>
        <visual name='visual'>
          <geometry>
            <mesh>
              <uri>model://big_plant/mesh/big_plant.stl</uri>
              <scale>1 1 1</scale>
            </mesh>
          </geometry>
        </visual>
        <collision name='collision'>
          <geometry>
            <box>
              <size>0.5 0.5 1.0</size>
            </box>
          </geometry>
        </collision>
      </link>
    </model>

    <model name='plant_1_2'>
      <static>true</static>
      <link name='link'>
        <pose>4.0 -1.0 0 0 0 0</pose>
        <visual name='visual'>
          <geometry>
            <mesh>
              <uri>model://big_plant/mesh/big_plant.stl</uri>
              <scale>1 1 1</scale>
            </mesh>
          </geometry>
        </visual>
        <collision name='collision'>
          <geometry>
            <box>
              <size>0.5 0.5 1.0</size>
            </box>
          </geometry>
        </collision>
      </link>
    </model>

    <model name='plant_2_1'>
      <static>true</static>
      <link name='link'>
        <pose>3.0 1.0 0 0 0 0</pose>
        <visual name='visual'>
          <geometry>
            <mesh>
              <uri>model://big_plant/mesh/big_plant.stl</uri>
              <scale>1 1 1</scale>
            </mesh>
          </geometry>
        </visual>
        <collision name='collision'>
          <geometry>
            <box>
              <size>0.5 0.5 1.0</size>
            </box>
          </geometry>
        </collision>
      </link>
    </model>

    <model name='plant_2_2'>
      <static>true</static>
      <link name='link'>
        <pose>4.0 1.0 0 0 0 0</pose>
        <visual name='visual'>
          <geometry>
            <mesh>
              <uri>model://big_plant/mesh/big_plant.stl</uri>
              <scale>1 1 1</scale>
            </mesh>
          </geometry>
        </visual>
        <collision name='collision'>
          <geometry>
            <box>
              <size>0.5 0.5 1.0</size>
            </box>
          </geometry>
        </collision>
      </link>
    </model>
    <model name='AgriBot'>
      <link name='base_link'>
        <inertial>
          <pose>-0.037202 -0.024649 -0.219935 0 -0 0</pose>
          <mass>44.067399999999999</mass>
          <inertia>
            <ixx>1.25047</ixx>
            <ixy>0.0042766000000000002</ixy>
            <ixz>0.027268799999999999</ixz>
            <iyy>3.2513200000000002</iyy>
            <iyz>9.5051199999999996e-05</iyz>
            <izz>4.2488900000000003</izz>
          </inertia>
        </inertial>
        <collision name='base_link_collision'>
          <pose>0 0 0 0 0 0</pose>
          <geometry>
            <mesh>
              <scale>1 1 1</scale>
              <uri>model://agribotv2/meshes/base_link.STL</uri>
            </mesh>
          </geometry>
          <surface>
            <contact>
              <ode/>
            </contact>
            <friction>
              <ode/>
            </friction>
          </surface>
        </collision>
        <collision name='base_link_fixed_joint_lump__Seeder_collision_1'>
          <pose>0.121937506662726 -0.0244867375890883 -0.293552999840268 0 0 -3.14159265358979</pose>
          <geometry>
            <mesh>
              <scale>1 1 1</scale>
              <uri>model://agribotv2/meshes/Seeder.STL</uri>
            </mesh>
          </geometry>
        </collision>
        <collision name='base_link_fixed_joint_lump__Camera_collision_2'>
          <pose>0.40143750666272 -0.0333712085079144 -0.33676308034937 0 0 0</pose>
          <geometry>
            <mesh>
              <scale>1 1 1</scale>
              <uri>model://agribotv2/meshes/Camera.STL</uri>
            </mesh>
          </geometry>
          <surface>
            <contact>
              <ode/>
            </contact>
            <friction>
              <ode/>
            </friction>
          </surface>
        </collision>
        <collision name='base_link_fixed_joint_lump__US1_collision_3'>
          <pose>0.138074753587277 -0.422471907443304 -0.311999999999983 1.5707963267949 0 -0.62831853071796</pose>
          <geometry>
            <mesh>
              <scale>1 1 1</scale>
              <uri>model://agribotv2/meshes/US1.STL</uri>
            </mesh>
          </geometry>
          <surface>
            <contact>
              <ode/>
            </contact>
            <friction>
              <ode/>
            </friction>
          </surface>
        </collision>
        <collision name='base_link_fixed_joint_lump__US2_collision_4'>
          <pose>0.391068810466621 -0.281804434077445 -0.311999999999983 -1.5707963267949 0 0</pose>
          <geometry>
            <mesh>
              <scale>1 1 1</scale>
              <uri>model://agribotv2/meshes/US2.STL</uri>
            </mesh>
          </geometry>
          <surface>
            <contact>
              <ode/>
            </contact>
            <friction>
              <ode/>
            </friction>
          </surface>
        </collision>
        <collision name='base_link_fixed_joint_lump__US3_collision_5'>
          <pose>0.391068810466623 0.232830958899269 -0.311999999999983 1.5707963267949 0 -0.372456753034098</pose>
          <geometry>
            <mesh>
              <scale>1 1 1</scale>
              <uri>model://agribotv2/meshes/US3.STL</uri>
            </mesh>
          </geometry>
          <surface>
            <contact>
              <ode/>
            </contact>
            <friction>
              <ode/>
            </friction>
          </surface>
        </collision>
        <collision name='base_link_fixed_joint_lump__US4_collision_6'>
          <pose>0.13807475358728 0.373498432265127 -0.311999999999983 1.5707963267949 0 0.62831853071796</pose>
          <geometry>
            <mesh>
              <scale>1 1 1</scale>
              <uri>model://agribotv2/meshes/US4.STL</uri>
            </mesh>
          </geometry>
          <surface>
            <contact>
              <ode/>
            </contact>
            <friction>
              <ode/>
            </friction>
          </surface>
        </collision>
        <visual name='base_link_visual'>
          <pose>0 0 0 0 0 0</pose>
          <geometry>
            <mesh>
              <scale>1 1 1</scale>
              <uri>model://agribotv2/meshes/base_link.STL</uri>
            </mesh>
          </geometry>
          <material>
            <diffuse>1 1 1 1</diffuse>
            <ambient>1 1 1 1</ambient>
          </material>
        </visual>
        <visual name='base_link_fixed_joint_lump__Seeder_visual_1'>
          <pose>0.121937506662726 -0.0244867375890883 -0.293552999840268 0 0 -3.14159265358979</pose>
          <geometry>
            <mesh>
              <scale>1 1 1</scale>
              <uri>model://agribotv2/meshes/Seeder.STL</uri>
            </mesh>
          </geometry>
          <material>
            <diffuse>0 0 1 1</diffuse>
            <ambient>0 0 1 1</ambient>
          </material>
        </visual>
        <visual name='base_link_fixed_joint_lump__Camera_visual_2'>
          <pose>0.40143750666272 -0.0333712085079144 -0.33676308034937 0 0 0</pose>
          <geometry>
            <mesh>
              <scale>1 1 1</scale>
              <uri>model://agribotv2/meshes/Camera.STL</uri>
            </mesh>
          </geometry>
          <material>
            <diffuse>0.990196 1 1 1</diffuse>
            <ambient>0.990196 1 1 1</ambient>
          </material>
        </visual>
        <visual name='base_link_fixed_joint_lump__US1_visual_3'>
          <pose>0.138074753587277 -0.422471907443304 -0.311999999999983 1.5707963267949 0 -0.62831853071796</pose>
          <geometry>
            <mesh>
              <scale>1 1 1</scale>
              <uri>model://agribotv2/meshes/US1.STL</uri>
            </mesh>
          </geometry>
          <material>
            <diffuse>0.372549 0.372549 0.372549 1</diffuse>
            <ambient>0.372549 0.372549 0.372549 1</ambient>
          </material>
        </visual>
        <visual name='base_link_fixed_joint_lump__US2_visual_4'>
          <pose>0.391068810466621 -0.281804434077445 -0.311999999999983 -1.5707963267949 0 0</pose>
          <geometry>
            <mesh>
              <scale>1 1 1</scale>
              <uri>model://agribotv2/meshes/US2.STL</uri>
            </mesh>
          </geometry>
          <material>
            <diffuse>0.372549 0.372549 0.372549 1</diffuse>
            <ambient>0.372549 0.372549 0.372549 1</ambient>
          </material>
        </visual>
        <visual name='base_link_fixed_joint_lump__US3_visual_5'>
          <pose>0.391068810466623 0.232830958899269 -0.311999999999983 1.5707963267949 0 -0.372456753034098</pose>
          <geometry>
            <mesh>
              <scale>1 1 1</scale>
              <uri>model://agribotv2/meshes/US3.STL</uri>
            </mesh>
          </geometry>
          <material>
            <diffuse>0.372549 0.372549 0.372549 1</diffuse>
            <ambient>0.372549 0.372549 0.372549 1</ambient>
          </material>
        </visual>
        <visual name='base_link_fixed_joint_lump__US4_visual_6'>
          <pose>0.13807475358728 0.373498432265127 -0.311999999999983 1.5707963267949 0 0.62831853071796</pose>
          <geometry>
            <mesh>
              <scale>1 1 1</scale>
              <uri>model://agribotv2/meshes/US4.STL</uri>
            </mesh>
          </geometry>
          <material>
            <diffuse>0.372549 0.372549 0.372549 1</diffuse>
            <ambient>0.372549 0.372549 0.372549 1</ambient>
          </material>
        </visual>
        <sensor name='imu_sensor' type='imu'>
          <pose>0 0 0 0 -0 0</pose>
          <topic>imu</topic>
          <update_rate>100</update_rate>
          <enable_metrics>false</enable_metrics>
          <imu>
            <orientation_reference_frame>
              <localization>CUSTOM</localization>
              <custom_rpy>0 0 0</custom_rpy>
              <grav_dir_x>1 0 0</grav_dir_x>
            </orientation_reference_frame>
            <angular_velocity>
              <x>
                <noise type='none'>
                  <mean>0</mean>
                  <stddev>0</stddev>
                  <bias_mean>0</bias_mean>
                  <bias_stddev>0</bias_stddev>
                  <dynamic_bias_stddev>0</dynamic_bias_stddev>
                  <dynamic_bias_correlation_time>0</dynamic_bias_correlation_time>
                  <precision>0</precision>
                </noise>
              </x>
              <y>
                <noise type='none'>
                  <mean>0</mean>
                  <stddev>0</stddev>
                  <bias_mean>0</bias_mean>
                  <bias_stddev>0</bias_stddev>
                  <dynamic_bias_stddev>0</dynamic_bias_stddev>
                  <dynamic_bias_correlation_time>0</dynamic_bias_correlation_time>
                  <precision>0</precision>
                </noise>
              </y>
              <z>
                <noise type='none'>
                  <mean>0</mean>
                  <stddev>0</stddev>
                  <bias_mean>0</bias_mean>
                  <bias_stddev>0</bias_stddev>
                  <dynamic_bias_stddev>0</dynamic_bias_stddev>
                  <dynamic_bias_correlation_time>0</dynamic_bias_correlation_time>
                  <precision>0</precision>
                </noise>
              </z>
            </angular_velocity>
            <linear_acceleration>
              <x>
                <noise type='none'>
                  <mean>0</mean>
                  <stddev>0</stddev>
                  <bias_mean>0</bias_mean>
                  <bias_stddev>0</bias_stddev>
                  <dynamic_bias_stddev>0</dynamic_bias_stddev>
                  <dynamic_bias_correlation_time>0</dynamic_bias_correlation_time>
                  <precision>0</precision>
                </noise>
              </x>
              <y>
                <noise type='none'>
                  <mean>0</mean>
                  <stddev>0</stddev>
                  <bias_mean>0</bias_mean>
                  <bias_stddev>0</bias_stddev>
                  <dynamic_bias_stddev>0</dynamic_bias_stddev>
                  <dynamic_bias_correlation_time>0</dynamic_bias_correlation_time>
                  <precision>0</precision>
                </noise>
              </y>
              <z>
                <noise type='none'>
                  <mean>0</mean>
                  <stddev>0</stddev>
                  <bias_mean>0</bias_mean>
                  <bias_stddev>0</bias_stddev>
                  <dynamic_bias_stddev>0</dynamic_bias_stddev>
                  <dynamic_bias_correlation_time>0</dynamic_bias_correlation_time>
                  <precision>0</precision>
                </noise>
              </z>
            </linear_acceleration>
            <enable_orientation>true</enable_orientation>
          </imu>
        </sensor>
        <sensor name='gps_sensor' type='navsat'>
          <always_on>true</always_on>
          <update_rate>1</update_rate>
          <topic>gps/fix</topic>
          <gps/>
        </sensor>
        <sensor name='camera' type='camera'>
          <pose>0.401438 -0.033371 -0.336763 0 -0 0</pose>
          <topic>/camera/image_raw</topic>
          <update_rate>30</update_rate>
          <enable_metrics>false</enable_metrics>
          <camera name='__default__'>
            <pose>0 0 0 0 -0 0</pose>
            <horizontal_fov>1.0469999999999999</horizontal_fov>
            <image>
              <width>640</width>
              <height>480</height>
              <format>RGB_INT8</format>
              <anti_aliasing>4</anti_aliasing>
            </image>
            <camera_info_topic>__default__</camera_info_topic>
            <trigger_topic></trigger_topic>
            <triggered>false</triggered>
            <clip>
              <near>0.10000000000000001</near>
              <far>100</far>
            </clip>
            <save enabled='false'>
              <path>__default__</path>
            </save>
            <visibility_mask>4294967295</visibility_mask>
            <noise>
              <type>none</type>
              <mean>0</mean>
              <stddev>0</stddev>
            </noise>
            <distortion>
              <k1>0</k1>
              <k2>0</k2>
              <k3>0</k3>
              <p1>0</p1>
              <p2>0</p2>
              <center>0.5 0.5</center>
            </distortion>
            <lens>
              <type>stereographic</type>
              <scale_to_hfov>true</scale_to_hfov>
              <cutoff_angle>1.5708</cutoff_angle>
              <env_texture_size>256</env_texture_size>
            </lens>
            <optical_frame_id></optical_frame_id>
          </camera>
        </sensor>
        <sensor name='US1_sensor' type='gpu_lidar'>
          <pose>0.138075 -0.422472 -0.312 0 0 -0.628319</pose>
          <topic>/ultra/us1</topic>
          <update_rate>20</update_rate>
          <enable_metrics>false</enable_metrics>
          <lidar>
            <scan>
              <horizontal>
                <samples>60</samples>
                <resolution>1</resolution>
                <min_angle>-0.52359999999999995</min_angle>
                <max_angle>0.52359999999999995</max_angle>
              </horizontal>
              <vertical>
                <samples>1</samples>
                <min_angle>0</min_angle>
                <max_angle>0</max_angle>
                <resolution>1</resolution>
              </vertical>
            </scan>
            <range>
              <min>0.25</min>
              <max>4</max>
              <resolution>0.01</resolution>
            </range>
            <noise>
              <type>none</type>
              <mean>0</mean>
              <stddev>0</stddev>
            </noise>
            <visibility_mask>4294967295</visibility_mask>
          </lidar>
        </sensor>
        <sensor name='US2_sensor' type='gpu_lidar'>
          <pose>0.45 -0.281804 -0.312 0 -0 0</pose>
          <topic>/ultra/us2</topic>
          <update_rate>20</update_rate>
          <enable_metrics>false</enable_metrics>
          <lidar>
            <scan>
              <horizontal>
                <samples>60</samples>
                <resolution>1</resolution>
                <min_angle>-0.52359999999999995</min_angle>
                <max_angle>0.52359999999999995</max_angle>
              </horizontal>
              <vertical>
                <samples>1</samples>
                <min_angle>0</min_angle>
                <max_angle>0</max_angle>
                <resolution>1</resolution>
              </vertical>
            </scan>
            <range>
              <min>0.25</min>
              <max>4</max>
              <resolution>0.01</resolution>
            </range>
            <noise>
              <type>none</type>
              <mean>0</mean>
              <stddev>0</stddev>
            </noise>
            <visibility_mask>4294967295</visibility_mask>
          </lidar>
        </sensor>
        <sensor name='US3_sensor' type='gpu_lidar'>
          <pose>0.45 0.232831 -0.312 0 0 -0.372457</pose>
          <topic>/ultra/us3</topic>
          <update_rate>20</update_rate>
          <enable_metrics>false</enable_metrics>
          <lidar>
            <scan>
              <horizontal>
                <samples>60</samples>
                <resolution>1</resolution>
                <min_angle>-0.52359999999999995</min_angle>
                <max_angle>0.52359999999999995</max_angle>
              </horizontal>
              <vertical>
                <samples>1</samples>
                <min_angle>0</min_angle>
                <max_angle>0</max_angle>
                <resolution>1</resolution>
              </vertical>
            </scan>
            <range>
              <min>0.25</min>
              <max>4</max>
              <resolution>0.01</resolution>
            </range>
            <noise>
              <type>none</type>
              <mean>0</mean>
              <stddev>0</stddev>
            </noise>
            <visibility_mask>4294967295</visibility_mask>
          </lidar>
        </sensor>
        <sensor name='US4_sensor' type='gpu_lidar'>
          <pose>0.138075 0.373498 -0.312 0 -0 0.628319</pose>
          <topic>/ultra/us4</topic>
          <update_rate>20</update_rate>
          <enable_metrics>false</enable_metrics>
          <lidar>
            <scan>
              <horizontal>
                <samples>60</samples>
                <resolution>1</resolution>
                <min_angle>-0.52359999999999995</min_angle>
                <max_angle>0.52359999999999995</max_angle>
              </horizontal>
              <vertical>
                <samples>1</samples>
                <min_angle>0</min_angle>
                <max_angle>0</max_angle>
                <resolution>1</resolution>
              </vertical>
            </scan>
            <range>
              <min>0.25</min>
              <max>4</max>
              <resolution>0.01</resolution>
            </range>
            <noise>
              <type>none</type>
              <mean>0</mean>
              <stddev>0</stddev>
            </noise>
            <visibility_mask>4294967295</visibility_mask>
          </lidar>
        </sensor>
        <pose>0 0 0 0 -0 0</pose>
        <enable_wind>false</enable_wind>
      </link>
      <joint name='Wheel1J' type='revolute'>
        <pose>0 0 0 0 -0 0</pose>
        <parent>base_link</parent>
        <child>Wheel1</child>
        <axis>
          <xyz>0 1 0</xyz>
          <limit>
            <lower>-10000000000000000</lower>
            <upper>10000000000000000</upper>
            <effort>200</effort>
            <velocity>1000</velocity>
            <stiffness>100000000</stiffness>
            <dissipation>1</dissipation>
          </limit>
          <dynamics>
            <spring_reference>0</spring_reference>
            <spring_stiffness>0</spring_stiffness>
            <damping>0.34999999999999998</damping>
            <friction>8</friction>
          </dynamics>
        </axis>
      </joint>
      <link name='Wheel1'>
        <pose>0.433438 -0.450476 -0.567 0 0 -0</pose>
        <inertial>
          <pose>0.000308 -0.003505 0.000664 0 -0 0</pose>
          <mass>1.0355700000000001</mass>
          <inertia>
            <ixx>0.0027661399999999998</ixx>
            <ixy>-3.0102900000000002e-07</ixy>
            <ixz>3.0140599999999999e-07</ixz>
            <iyy>0.0049063300000000004</iyy>
            <iyz>-6.55323e-07</iyz>
            <izz>0.0027666600000000002</izz>
          </inertia>
        </inertial>
        <collision name='Wheel1_collision'>
          <pose>0 0 0 0 0 0</pose>
          <geometry>
            <mesh>
              <scale>1 1 1</scale>
              <uri>model://agribotv2/meshes/Wheel1.STL</uri>
            </mesh>
          </geometry>
          <surface>
            <friction>
              <ode>
                <mu>0</mu>
                <mu2>0</mu2>
              </ode>
            </friction>
          </surface>
        </collision>
        <visual name='Wheel1_visual'>
          <pose>0 0 0 0 0 0</pose>
          <geometry>
            <mesh>
              <scale>1 1 1</scale>
              <uri>model://agribotv2/meshes/Wheel1.STL</uri>
            </mesh>
          </geometry>
          <material>
            <diffuse>0 0 0 1</diffuse>
            <ambient>0 0 0 1</ambient>
          </material>
        </visual>
        <enable_wind>false</enable_wind>
      </link>
      <joint name='Wheel2J' type='revolute'>
        <pose>0 0 0 0 -0 0</pose>
        <parent>base_link</parent>
        <child>Wheel2</child>
        <axis>
          <xyz>0 1 0</xyz>
          <limit>
            <lower>-10000000000000000</lower>
            <upper>10000000000000000</upper>
            <effort>200</effort>
            <velocity>1000</velocity>
            <stiffness>100000000</stiffness>
            <dissipation>1</dissipation>
          </limit>
          <dynamics>
            <spring_reference>0</spring_reference>
            <spring_stiffness>0</spring_stiffness>
            <damping>0.34999999999999998</damping>
            <friction>8</friction>
          </dynamics>
        </axis>
      </joint>
      <link name='Wheel2'>
        <pose>-0.476562 -0.45536 -0.567 -0 -0 -0</pose>
        <inertial>
          <pose>0.000505 0.00138 0.000529 0 -0 0</pose>
          <mass>1.0355700000000001</mass>
          <inertia>
            <ixx>0.0027663800000000001</ixx>
            <ixy>-4.9660599999999999e-07</ixy>
            <ixz>3.9474e-07</ixz>
            <iyy>0.0049063300000000004</iyy>
            <iyz>-5.2292499999999995e-07</iyz>
            <izz>0.0027664199999999999</izz>
          </inertia>
        </inertial>
        <collision name='Wheel2_collision'>
          <pose>0 0 0 0 0 0</pose>
          <geometry>
            <mesh>
              <scale>1 1 1</scale>
              <uri>model://agribotv2/meshes/Wheel2.STL</uri>
            </mesh>
          </geometry>
          <surface>
            <friction>
              <ode>
                <mu>0</mu>
                <mu2>0</mu2>
              </ode>
            </friction>
          </surface>
        </collision>
        <visual name='Wheel2_visual'>
          <pose>0 0 0 0 0 0</pose>
          <geometry>
            <mesh>
              <scale>1 1 1</scale>
              <uri>model://agribotv2/meshes/Wheel2.STL</uri>
            </mesh>
          </geometry>
          <material>
            <diffuse>0 0 0 1</diffuse>
            <ambient>0 0 0 1</ambient>
          </material>
        </visual>
        <enable_wind>false</enable_wind>
      </link>
      <joint name='Wheel3J' type='revolute'>
        <pose>0 0 0 0 -0 0</pose>
        <parent>base_link</parent>
        <child>Wheel3</child>
        <axis>
          <xyz>0 1 0</xyz>
          <limit>
            <lower>-10000000000000000</lower>
            <upper>10000000000000000</upper>
            <effort>200</effort>
            <velocity>1000</velocity>
            <stiffness>100000000</stiffness>
            <dissipation>1</dissipation>
          </limit>
          <dynamics>
            <spring_reference>0</spring_reference>
            <spring_stiffness>0</spring_stiffness>
            <damping>0.34999999999999998</damping>
            <friction>8</friction>
          </dynamics>
        </axis>
      </joint>
      <link name='Wheel3'>
        <pose>-0.476562 0.406387 -0.567 -0 -0 -0</pose>
        <inertial>
          <pose>0.000308 -0.00138 -0.000664 0 -0 0</pose>
          <mass>1.0355700000000001</mass>
          <inertia>
            <ixx>0.0027661399999999998</ixx>
            <ixy>3.0102900000000002e-07</ixy>
            <ixz>-3.0140599999999999e-07</ixz>
            <iyy>0.0049063300000000004</iyy>
            <iyz>-6.55323e-07</iyz>
            <izz>0.0027666600000000002</izz>
          </inertia>
        </inertial>
        <collision name='Wheel3_collision'>
          <pose>0 0 0 0 0 0</pose>
          <geometry>
            <mesh>
              <scale>1 1 1</scale>
              <uri>model://agribotv2/meshes/Wheel3.STL</uri>
            </mesh>
          </geometry>
          <surface>
            <friction>
              <ode>
                <mu>0</mu>
                <mu2>0</mu2>
              </ode>
            </friction>
          </surface>
        </collision>
        <visual name='Wheel3_visual'>
          <pose>0 0 0 0 0 0</pose>
          <geometry>
            <mesh>
              <scale>1 1 1</scale>
              <uri>model://agribotv2/meshes/Wheel3.STL</uri>
            </mesh>
          </geometry>
          <material>
            <diffuse>0 0 0 1</diffuse>
            <ambient>0 0 0 1</ambient>
          </material>
        </visual>
        <enable_wind>false</enable_wind>
      </link>
      <joint name='Wheel4J' type='revolute'>
        <pose>0 0 0 0 -0 0</pose>
        <parent>base_link</parent>
        <child>Wheel4</child>
        <axis>
          <xyz>0 1 0</xyz>
          <limit>
            <lower>-10000000000000000</lower>
            <upper>10000000000000000</upper>
            <effort>200</effort>
            <velocity>1000</velocity>
            <stiffness>100000000</stiffness>
            <dissipation>1</dissipation>
          </limit>
          <dynamics>
            <spring_reference>0</spring_reference>
            <spring_stiffness>0</spring_stiffness>
            <damping>0.34999999999999998</damping>
            <friction>8</friction>
          </dynamics>
        </axis>
      </joint>
      <link name='Wheel4'>
        <pose>0.433438 0.411271 -0.567 -0 -0 -0</pose>
        <inertial>
          <pose>-0.000308 -0.006264 0.000664 0 -0 0</pose>
          <mass>1.0355700000000001</mass>
          <inertia>
            <ixx>0.0027661399999999998</ixx>
            <ixy>-3.0102900000000002e-07</ixy>
            <ixz>-3.0140599999999999e-07</ixz>
            <iyy>0.0049063300000000004</iyy>
            <iyz>6.55323e-07</iyz>
            <izz>0.0027666600000000002</izz>
          </inertia>
        </inertial>
        <collision name='Wheel4_collision'>
          <pose>0 0 0 0 0 0</pose>
          <geometry>
            <mesh>
              <scale>1 1 1</scale>
              <uri>model://agribotv2/meshes/Wheel4.STL</uri>
            </mesh>
          </geometry>
          <surface>
            <friction>
              <ode>
                <mu>0</mu>
                <mu2>0</mu2>
              </ode>
            </friction>
          </surface>
        </collision>
        <visual name='Wheel4_visual'>
          <pose>0 0 0 0 0 0</pose>
          <geometry>
            <mesh>
              <scale>1 1 1</scale>
              <uri>model://agribotv2/meshes/Wheel4.STL</uri>
            </mesh>
          </geometry>
          <material>
            <diffuse>0 0 0 1</diffuse>
            <ambient>0 0 0 1</ambient>
          </material>
        </visual>
        <enable_wind>false</enable_wind>
      </link>
      <plugin name='ignition::gazebo::systems::DiffDrive' filename='libignition-gazebo-diff-drive-system.so'>
        <left_joint>Wheel4J</left_joint>
        <right_joint>Wheel1J</right_joint>
        <wheel_separation>0.866</wheel_separation>
        <wheel_radius>0.1</wheel_radius>
        <odom_publish_frequency>1</odom_publish_frequency>
        <topic>/cmd_vel</topic>
        <odom_topic>/odometry</odom_topic>
        <tf_topic>/tf_gazebo</tf_topic>
        <frame_id>odom</frame_id>
        <child_frame_id>base_link</child_frame_id>
        <max_linear_acceleration>20.0</max_linear_acceleration>
        <min_linear_acceleration>-20.0</min_linear_acceleration>
        <max_angular_acceleration>20.0</max_angular_acceleration>
        <min_angular_acceleration>-20.0</min_angular_acceleration>
        <max_linear_velocity>4.0</max_linear_velocity>
        <min_linear_velocity>-4.0</min_linear_velocity>
        <max_angular_velocity>4.0</max_angular_velocity>
        <min_angular_velocity>-4.0</min_angular_velocity>
      </plugin>
      <plugin name='ignition::gazebo::systems::DiffDrive' filename='libignition-gazebo-diff-drive-system.so'>
        <left_joint>Wheel3J</left_joint>
        <right_joint>Wheel2J</right_joint>
        <wheel_separation>0.866</wheel_separation>
        <wheel_radius>0.1</wheel_radius>
        <odom_publish_frequency>1</odom_publish_frequency>
        <topic>/cmd_vel</topic>
        <max_linear_acceleration>20.0</max_linear_acceleration>
        <min_linear_acceleration>-20.0</min_linear_acceleration>
        <max_angular_acceleration>20.0</max_angular_acceleration>
        <min_angular_acceleration>-20.0</min_angular_acceleration>
        <max_linear_velocity>4.0</max_linear_velocity>
        <min_linear_velocity>-4.0</min_linear_velocity>
        <max_angular_velocity>4.0</max_angular_velocity>
        <min_angular_velocity>-4.0</min_angular_velocity>
      </plugin>
      <plugin name='ignition::gazebo::systems::JointStatePublisher' filename='libignition-gazebo-joint-state-publisher-system.so'>
        <topic>joint_states</topic>
        <joint_name>Wheel1J</joint_name>
        <joint_name>Wheel2J</joint_name>
        <joint_name>Wheel3J</joint_name>
        <joint_name>Wheel4J</joint_name>
      </plugin>
      <frame name='SeederJ' attached_to='base_link'>
        <pose>0.121938 -0.024487 -0.293553 0 0 -3.14159</pose>
      </frame>
      <frame name='Seeder' attached_to='SeederJ'/>
      <frame name='camJ' attached_to='base_link'>
        <pose>0.401438 -0.033371 -0.336763 0 -0 0</pose>
      </frame>
      <frame name='Camera' attached_to='camJ'/>
      <frame name='us1J' attached_to='base_link'>
        <pose>0.138075 -0.422472 -0.312 1.5708 -0 -0.628319</pose>
      </frame>
      <frame name='US1' attached_to='us1J'/>
      <frame name='us2J' attached_to='base_link'>
        <pose>0.391069 -0.281804 -0.312 -1.5708 0 0</pose>
      </frame>
      <frame name='US2' attached_to='us2J'/>
      <frame name='us3J' attached_to='base_link'>
        <pose>0.391069 0.232831 -0.312 1.5708 -0 -0.372457</pose>
      </frame>
      <frame name='US3' attached_to='us3J'/>
      <frame name='us4J' attached_to='base_link'>
        <pose>0.138075 0.373498 -0.312 1.5708 -0 0.628319</pose>
      </frame>
      <frame name='US4' attached_to='us4J'/>
      <pose>0 1.2e-05 0.693489 -1.7e-05 0 0</pose>
      <static>false</static>
      <self_collide>false</self_collide>
    </model>
    <light name='sun' type='directional'>
      <pose>0 0 10 0 -0 0</pose>
      <cast_shadows>true</cast_shadows>
      <intensity>1</intensity>
      <direction>-0.5 0.1 -0.9</direction>
      <diffuse>0.8 0.8 0.8 1</diffuse>
      <specular>0.2 0.2 0.2 1</specular>
      <attenuation>
        <range>1000</range>
        <linear>0.01</linear>
        <constant>0.90000000000000002</constant>
        <quadratic>0.001</quadratic>
      </attenuation>
      <spot>
        <inner_angle>0</inner_angle>
        <outer_angle>0</outer_angle>
        <falloff>0</falloff>
      </spot>
    </light>
  </world>
</sdf>
